<?xml version="1.0" ?>
<robot name="rover_urdf_wheels" xmlns:xacro="http://www.ros.org/wiki/xacro">

<xacro:include filename="$(find rover_base_description)/urdf/rover_urdf_wheels.trans" />
<link name="base_link">
  <inertial>
    <origin xyz="0.00738439904217671 -0.09190109455538922 0.39234360337449" rpy="0 0 0"/>
    <mass value="61.720930628843746"/>
    <inertia ixx="4.799832" iyy="7.189427" izz="8.8691" ixy="0.012105" iyz="-0.602757" ixz="0.03608"/>
  </inertial>
  <visual>
    <origin xyz="0 0 0" rpy="0 0 0"/>
    <geometry>
      <mesh filename="file://$(find rover_base_description)/meshes/base_link.stl" scale="0.001 0.001 0.001"/>
    </geometry>
    <material name="silver"/>
  </visual>
  <collision>
    <origin xyz="0 0 0" rpy="0 0 0"/>
    <geometry>
      <mesh filename="file://$(find rover_base_description)/meshes/base_link.stl" scale="0.001 0.001 0.001"/>
    </geometry>
  </collision>
</link>

<link name="left_front_wheel_1">
  <inertial>
    <origin xyz="0.09201346295520074 6.528691856022562e-07 -4.5004461016184827e-07" rpy="0 0 0"/>
    <mass value="19.087823413323793"/>
    <inertia ixx="0.183083" iyy="0.107707" izz="0.107708" ixy="0.0" iyz="-0.0" ixz="-0.0"/>
  </inertial>
  <visual>
    <origin xyz="-0.433095 0.598852 -0.186096" rpy="0 0 0"/>
    <geometry>
      <mesh filename="file://$(find rover_base_description)/meshes/left_front_wheel_1.stl" scale="0.001 0.001 0.001"/>
    </geometry>
    <material name="silver"/>
  </visual>
  <collision>
    <origin xyz="-0.433095 0.598852 -0.186096" rpy="0 0 0"/>
    <geometry>
      <mesh filename="file://$(find rover_base_description)/meshes/left_front_wheel_1.stl" scale="0.001 0.001 0.001"/>
    </geometry>
  </collision>
</link>

<link name="left_middle_wheel_1">
  <inertial>
    <origin xyz="0.09201346295520813 -4.6810125314822315e-07 6.332213909610029e-07" rpy="0 0 0"/>
    <mass value="19.087823413323793"/>
    <inertia ixx="0.183083" iyy="0.107708" izz="0.107707" ixy="0.0" iyz="0.0" ixz="0.0"/>
  </inertial>
  <visual>
    <origin xyz="-0.437475 0.171234 -0.173524" rpy="0 0 0"/>
    <geometry>
      <mesh filename="file://$(find rover_base_description)/meshes/left_middle_wheel_1.stl" scale="0.001 0.001 0.001"/>
    </geometry>
    <material name="silver"/>
  </visual>
  <collision>
    <origin xyz="-0.437475 0.171234 -0.173524" rpy="0 0 0"/>
    <geometry>
      <mesh filename="file://$(find rover_base_description)/meshes/left_middle_wheel_1.stl" scale="0.001 0.001 0.001"/>
    </geometry>
  </collision>
</link>

<link name="left_back_wheel_1">
  <inertial>
    <origin xyz="0.09201346295520191 -3.313596602660951e-08 2.453629426579784e-07" rpy="0 0 0"/>
    <mass value="19.087823413323793"/>
    <inertia ixx="0.183083" iyy="0.107708" izz="0.107707" ixy="0.0" iyz="0.0" ixz="0.0"/>
  </inertial>
  <visual>
    <origin xyz="-0.433475 -0.244602 -0.142087" rpy="0 0 0"/>
    <geometry>
      <mesh filename="file://$(find rover_base_description)/meshes/left_back_wheel_1.stl" scale="0.001 0.001 0.001"/>
    </geometry>
    <material name="silver"/>
  </visual>
  <collision>
    <origin xyz="-0.433475 -0.244602 -0.142087" rpy="0 0 0"/>
    <geometry>
      <mesh filename="file://$(find rover_base_description)/meshes/left_back_wheel_1.stl" scale="0.001 0.001 0.001"/>
    </geometry>
  </collision>
</link>

<link name="right_back_wheel_1">
  <inertial>
    <origin xyz="-0.09201346295513935 4.3400863422582425e-07 -4.1137307060790107e-07" rpy="0 0 0"/>
    <mass value="19.087823413323793"/>
    <inertia ixx="0.183083" iyy="0.107708" izz="0.107707" ixy="-0.0" iyz="-0.0" ixz="0.0"/>
  </inertial>
  <visual>
    <origin xyz="0.433725 -0.242481 -0.142668" rpy="0 0 0"/>
    <geometry>
      <mesh filename="file://$(find rover_base_description)/meshes/right_back_wheel_1.stl" scale="0.001 0.001 0.001"/>
    </geometry>
    <material name="silver"/>
  </visual>
  <collision>
    <origin xyz="0.433725 -0.242481 -0.142668" rpy="0 0 0"/>
    <geometry>
      <mesh filename="file://$(find rover_base_description)/meshes/right_back_wheel_1.stl" scale="0.001 0.001 0.001"/>
    </geometry>
  </collision>
</link>

<link name="right_middle_wheel_1">
  <inertial>
    <origin xyz="-0.09201346295512652 3.8586665712658785e-07 -4.810204064231716e-07" rpy="0 0 0"/>
    <mass value="19.087823413323793"/>
    <inertia ixx="0.183083" iyy="0.107708" izz="0.107707" ixy="-0.0" iyz="-0.0" ixz="0.0"/>
  </inertial>
  <visual>
    <origin xyz="0.435725 0.173764 -0.16813" rpy="0 0 0"/>
    <geometry>
      <mesh filename="file://$(find rover_base_description)/meshes/right_middle_wheel_1.stl" scale="0.001 0.001 0.001"/>
    </geometry>
    <material name="silver"/>
  </visual>
  <collision>
    <origin xyz="0.435725 0.173764 -0.16813" rpy="0 0 0"/>
    <geometry>
      <mesh filename="file://$(find rover_base_description)/meshes/right_middle_wheel_1.stl" scale="0.001 0.001 0.001"/>
    </geometry>
  </collision>
</link>

<link name="right_front_wheel_1">
  <inertial>
    <origin xyz="-0.09201346295516599 -2.2772661723013954e-07 -3.4350903457824877e-07" rpy="0 0 0"/>
    <mass value="19.087823413323793"/>
    <inertia ixx="0.183083" iyy="0.107708" izz="0.107707" ixy="-0.0" iyz="-0.0" ixz="0.0"/>
  </inertial>
  <visual>
    <origin xyz="0.433725 0.60086 -0.192329" rpy="0 0 0"/>
    <geometry>
      <mesh filename="file://$(find rover_base_description)/meshes/right_front_wheel_1.stl" scale="0.001 0.001 0.001"/>
    </geometry>
    <material name="silver"/>
  </visual>
  <collision>
    <origin xyz="0.433725 0.60086 -0.192329" rpy="0 0 0"/>
    <geometry>
      <mesh filename="file://$(find rover_base_description)/meshes/right_front_wheel_1.stl" scale="0.001 0.001 0.001"/>
    </geometry>
  </collision>
</link>

<joint name="left_front_wheel_joint" type="continuous">
  <origin xyz="0.433095 -0.598852 0.186096" rpy="0 0 0"/>
  <parent link="base_link"/>
  <child link="left_front_wheel_1"/>
  <axis xyz="1.0 0.0 -0.0"/>
</joint>

<joint name="left_middle_wheel_joint" type="continuous">
  <origin xyz="0.437475 -0.171234 0.173524" rpy="0 0 0"/>
  <parent link="base_link"/>
  <child link="left_middle_wheel_1"/>
  <axis xyz="1.0 0.0 0.0"/>
</joint>

<joint name="left_back_wheel_joint" type="continuous">
  <origin xyz="0.433475 0.244602 0.142087" rpy="0 0 0"/>
  <parent link="base_link"/>
  <child link="left_back_wheel_1"/>
  <axis xyz="1.0 0.0 0.0"/>
</joint>

<joint name="right_back_wheel_joint" type="continuous">
  <origin xyz="-0.433725 0.242481 0.142668" rpy="0 0 0"/>
  <parent link="base_link"/>
  <child link="right_back_wheel_1"/>
  <axis xyz="-1.0 -0.0 -0.0"/>
</joint>

<joint name="right_middle_wheel_joint" type="continuous">
  <origin xyz="-0.435725 -0.173764 0.16813" rpy="0 0 0"/>
  <parent link="base_link"/>
  <child link="right_middle_wheel_1"/>
  <axis xyz="-1.0 -0.0 -0.0"/>
</joint>

<joint name="right_front_wheel_joint" type="continuous">
  <origin xyz="-0.433725 -0.60086 0.192329" rpy="0 0 0"/>
  <parent link="base_link"/>
  <child link="right_front_wheel_1"/>
  <axis xyz="-1.0 -0.0 0.0"/>
</joint>

</robot>
