<?xml version="1.0" ?>
<robot name="arm" xmlns:xacro="http://www.ros.org/wiki/xacro">

<link name="base_link">
  <inertial>
    <origin xyz="-0.0010063158166902576 -0.0023179609946681447 0.0025047768579964246" rpy="0 0 0"/>
    <mass value="0.8402300230207919"/>
    <inertia ixx="0.005299" iyy="0.003467" izz="0.008764" ixy="0.000215" iyz="-0.0" ixz="0.0"/>
  </inertial>
  <visual>
    <origin xyz="0 0 0" rpy="0 0 0"/>
    <geometry>
      <mesh filename="file://$(find arm_description)/meshes/base_link.stl" scale="0.001 0.001 0.001"/>
    </geometry>
    <material name="silver"/>
  </visual>
  <collision>
    <origin xyz="0 0 0" rpy="0 0 0"/>
    <geometry>
      <mesh filename="file://$(find arm_description)/meshes/base_link.stl" scale="0.001 0.001 0.001"/>
    </geometry>
  </collision>
</link>

<link name="waist_1">
  <inertial>
    <origin xyz="-7.702444876018025e-05 0.009830969674369704 0.02300113756943942" rpy="0 0 0"/>
    <mass value="0.8480827984091125"/>
    <inertia ixx="0.001213" iyy="0.002123" izz="0.002523" ixy="-7e-06" iyz="-8.3e-05" ixz="1e-06"/>
  </inertial>
  <visual>
    <origin xyz="-0.00646 0.027932 -0.005" rpy="0 0 0"/>
    <geometry>
      <mesh filename="file://$(find arm_description)/meshes/waist_1.stl" scale="0.001 0.001 0.001"/>
    </geometry>
    <material name="silver"/>
  </visual>
  <collision>
    <origin xyz="-0.00646 0.027932 -0.005" rpy="0 0 0"/>
    <geometry>
      <mesh filename="file://$(find arm_description)/meshes/waist_1.stl" scale="0.001 0.001 0.001"/>
    </geometry>
  </collision>
</link>

<link name="shoulder_1">
  <inertial>
    <origin xyz="2.8948591498393662e-05 -0.004074156190009087 0.23288965236006828" rpy="0 0 0"/>
    <mass value="2.3356160941174426"/>
    <inertia ixx="0.059486" iyy="0.060319" izz="0.002265" ixy="-7e-06" iyz="-0.000522" ixz="5e-06"/>
  </inertial>
  <visual>
    <origin xyz="-0.006461 0.027932 -0.0405" rpy="0 0 0"/>
    <geometry>
      <mesh filename="file://$(find arm_description)/meshes/shoulder_1.stl" scale="0.001 0.001 0.001"/>
    </geometry>
    <material name="silver"/>
  </visual>
  <collision>
    <origin xyz="-0.006461 0.027932 -0.0405" rpy="0 0 0"/>
    <geometry>
      <mesh filename="file://$(find arm_description)/meshes/shoulder_1.stl" scale="0.001 0.001 0.001"/>
    </geometry>
  </collision>
</link>

<link name="forearm_1">
  <inertial>
    <origin xyz="-0.0047246620557192965 0.22397119357725606 0.002083108957369073" rpy="0 0 0"/>
    <mass value="1.9893346240282717"/>
    <inertia ixx="0.050345" iyy="0.004096" izz="0.053666" ixy="0.001691" iyz="-0.000192" ixz="-1e-06"/>
  </inertial>
  <visual>
    <origin xyz="-0.006462 0.028078 -0.4905" rpy="0 0 0"/>
    <geometry>
      <mesh filename="file://$(find arm_description)/meshes/forearm_1.stl" scale="0.001 0.001 0.001"/>
    </geometry>
    <material name="silver"/>
  </visual>
  <collision>
    <origin xyz="-0.006462 0.028078 -0.4905" rpy="0 0 0"/>
    <geometry>
      <mesh filename="file://$(find arm_description)/meshes/forearm_1.stl" scale="0.001 0.001 0.001"/>
    </geometry>
  </collision>
</link>

<link name="wrist_1_1">
  <inertial>
    <origin xyz="-0.06568494427723634 0.001506419448577545 -0.0013244463243618498" rpy="0 0 0"/>
    <mass value="1.139710997448956"/>
    <inertia ixx="0.000461" iyy="0.002977" izz="0.002995" ixy="-0.00018" iyz="-6.2e-05" ixz="-8.6e-05"/>
  </inertial>
  <visual>
    <origin xyz="-0.002883 -0.421905 -0.492176" rpy="0 0 0"/>
    <geometry>
      <mesh filename="file://$(find arm_description)/meshes/wrist_1_1.stl" scale="0.001 0.001 0.001"/>
    </geometry>
    <material name="silver"/>
  </visual>
  <collision>
    <origin xyz="-0.002883 -0.421905 -0.492176" rpy="0 0 0"/>
    <geometry>
      <mesh filename="file://$(find arm_description)/meshes/wrist_1_1.stl" scale="0.001 0.001 0.001"/>
    </geometry>
  </collision>
</link>

<link name="wrist_2_1">
  <inertial>
    <origin xyz="-0.0001378319350452636 0.017225594312011316 -0.00031580323993046777" rpy="0 0 0"/>
    <mass value="0.1496451428941353"/>
    <inertia ixx="3.6e-05" iyy="6.6e-05" izz="5e-05" ixy="-0.0" iyz="-0.0" ixz="-1e-06"/>
  </inertial>
  <visual>
    <origin xyz="-0.002645 -0.451898 -0.491615" rpy="0 0 0"/>
    <geometry>
      <mesh filename="file://$(find arm_description)/meshes/wrist_2_1.stl" scale="0.001 0.001 0.001"/>
    </geometry>
    <material name="silver"/>
  </visual>
  <collision>
    <origin xyz="-0.002645 -0.451898 -0.491615" rpy="0 0 0"/>
    <geometry>
      <mesh filename="file://$(find arm_description)/meshes/wrist_2_1.stl" scale="0.001 0.001 0.001"/>
    </geometry>
  </collision>
</link>

<joint name="turret_joint" type="revolute">
  <origin xyz="0.00646 -0.027932 0.005" rpy="0 0 0"/>
  <parent link="base_link"/>
  <child link="waist_1"/>
  <axis xyz="0.0 0.0 1.0"/>
  <limit lower="${-pi/2}" upper="${pi/2}" effort="0.0" velocity="0.0"/>
</joint>

<joint name="shoulder_joint" type="revolute">
  <origin xyz="1e-06 0.0 0.0355" rpy="-0.289729 0 0"/>
  <parent link="waist_1"/>
  <child link="shoulder_1"/>
  <axis xyz="-0.999968 -0.007954 0.0"/>
  <limit lower="${-pi/2}" upper="-0.17" effort="0.0" velocity="0.0"/>
</joint>

<joint name="elbow_joint" type="revolute">
  <origin xyz="1e-06 -0.000146 0.45" rpy="-0.350289 0 0"/>
  <parent link="shoulder_1"/>
  <child link="forearm_1"/>
  <axis xyz="-0.999968 -0.007954 -0.0"/>
  <limit lower="-0.54" upper="0.42" effort="0.0" velocity="0.0"/>
</joint>

<joint name="wrist_pitch" type="revolute">
  <origin xyz="-0.003579 0.449983 0.001676" rpy="0.640018 0 0"/>
  <parent link="forearm_1"/>
  <child link="wrist_1_1"/>
  <axis xyz="-0.999968 -0.007954 -0.0"/>
  <limit lower="${-pi/2}" upper="${pi/2}" effort="0.0" velocity="0.0"/>
</joint>

<joint name="wrist_roll" type="revolute">
  <origin xyz="-0.000238 0.029993 -0.000561" rpy="0 0 0"/>
  <parent link="wrist_1_1"/>
  <child link="wrist_2_1"/>
  <axis xyz="-0.007952 0.999793 -0.018724"/>
  <limit lower="${-pi/2}" upper="${pi/2}" effort="0.0" velocity="0.0"/>
</joint>

</robot>
